<?xml version="1.0" ?>
<sdf version="1.8">
  <model name="maze_robot">
    <pose>-8 -8 0.3 0 0 0</pose>
    <static>false</static>
    
    <!-- Base Link -->
    <link name="base_link">
      <inertial>
        <mass>5.0</mass>
        <inertia>
          <ixx>0.0395</ixx>
          <iyy>0.0395</iyy>
          <izz>0.045</izz>
        </inertia>
      </inertial>
      
      <collision name="collision">
        <geometry>
          <cylinder>
            <radius>0.3</radius>
            <length>0.15</length>
          </cylinder>
        </geometry>
      </collision>
      
      <visual name="visual">
        <geometry>
          <cylinder>
            <radius>0.3</radius>
            <length>0.15</length>
          </cylinder>
        </geometry>
        <material>
          <ambient>1.0 0.0 0.0 1</ambient>
          <diffuse>1.0 0.2 0.0 1</diffuse>
          <emissive>0.5 0.0 0.0 1</emissive>
        </material>
      </visual>
      
      <!-- IMU Sensor -->
      <sensor name="imu_sensor" type="imu">
        <always_on>1</always_on>
        <update_rate>100</update_rate>
        <topic>imu</topic>
        <imu>
          <angular_velocity>
            <x>
              <noise type="gaussian">
                <mean>0.0</mean>
                <stddev>2e-4</stddev>
              </noise>
            </x>
            <y>
              <noise type="gaussian">
                <mean>0.0</mean>
                <stddev>2e-4</stddev>
              </noise>
            </y>
            <z>
              <noise type="gaussian">
                <mean>0.0</mean>
                <stddev>2e-4</stddev>
              </noise>
            </z>
          </angular_velocity>
          <linear_acceleration>
            <x>
              <noise type="gaussian">
                <mean>0.0</mean>
                <stddev>1.7e-2</stddev>
              </noise>
            </x>
            <y>
              <noise type="gaussian">
                <mean>0.0</mean>
                <stddev>1.7e-2</stddev>
              </noise>
            </y>
            <z>
              <noise type="gaussian">
                <mean>0.0</mean>
                <stddev>1.7e-2</stddev>
              </noise>
            </z>
          </linear_acceleration>
        </imu>
      </sensor>
      
      <!-- 2D Lidar  -->
      <sensor name="lidar" type="gpu_lidar">
        <pose>0 0 0.25 0 0 0</pose> 
        <topic>lidar</topic>
        <update_rate>10</update_rate>
        <ray>
          <scan>
            <horizontal>
              <samples>360</samples>
              <resolution>1</resolution>
              <min_angle>-3.14159</min_angle>
              <max_angle>3.14159</max_angle>
            </horizontal>
          </scan>
          <range>
            <min>0.35</min> 
            <max>10.0</max>
            <resolution>0.01</resolution>
          </range>
          <noise>
            <type>gaussian</type>
            <mean>0.0</mean>
            <stddev>0.01</stddev>
          </noise>
        </ray>
        <always_on>1</always_on>
        <visualize>true</visualize>
      </sensor>
      
      <!-- Camera-->
      <sensor name="bottom_camera" type="camera">
        <pose>0 0 -0.05 0 1.5708 0</pose>
        <topic>camera/bottom</topic>
        <update_rate>10</update_rate>
        <camera>
          <horizontal_fov>1.047</horizontal_fov>
          <image>
            <width>320</width>
            <height>240</height>
            <format>R8G8B8</format>
          </image>
          <clip>
            <near>0.01</near>
            <far>2.0</far>
          </clip>
        </camera>
        <always_on>1</always_on>
        <visualize>false</visualize>
      </sensor>
    </link>
    
    <!-- Left Wheel -->
    <link name="left_wheel">
      <pose relative_to="base_link">0 0.25 0 -1.5707 0 0</pose>
      <inertial>
        <mass>0.5</mass>
        <inertia>
          <ixx>0.0016</ixx>
          <iyy>0.0016</iyy>
          <izz>0.0016</izz>
        </inertia>
      </inertial>
      <collision name="collision">
        <geometry>
          <cylinder>
            <radius>0.15</radius>
            <length>0.05</length>
          </cylinder>
        </geometry>
      </collision>
      <visual name="visual">
        <geometry>
          <cylinder>
            <radius>0.15</radius>
            <length>0.05</length>
          </cylinder>
        </geometry>
        <material>
          <ambient>0.2 0.2 0.2 1</ambient>
          <diffuse>0.3 0.3 0.3 1</diffuse>
        </material>
      </visual>
    </link>
    
    <!-- Right Wheel -->
    <link name="right_wheel">
      <pose relative_to="base_link">0 -0.25 0 -1.5707 0 0</pose>
      <inertial>
        <mass>0.5</mass>
        <inertia>
          <ixx>0.0016</ixx>
          <iyy>0.0016</iyy>
          <izz>0.0016</izz>
        </inertia>
      </inertial>
      <collision name="collision">
        <geometry>
          <cylinder>
            <radius>0.15</radius>
            <length>0.05</length>
          </cylinder>
        </geometry>
      </collision>
      <visual name="visual">
        <geometry>
          <cylinder>
            <radius>0.15</radius>
            <length>0.05</length>
          </cylinder>
        </geometry>
        <material>
          <ambient>0.2 0.2 0.2 1</ambient>
          <diffuse>0.3 0.3 0.3 1</diffuse>
        </material>
      </visual>
    </link>
    
    <!-- Caster Wheel -->
    <link name="caster_wheel">
      <pose relative_to="base_link">0.2 0 -0.1 0 0 0</pose>
      <inertial>
        <mass>0.1</mass>
        <inertia>
          <ixx>0.0001</ixx>
          <iyy>0.0001</iyy>
          <izz>0.0001</izz>
        </inertia>
      </inertial>
      <collision name="collision">
        <geometry>
          <sphere>
            <radius>0.05</radius>
          </sphere>
        </geometry>
        <surface>
          <friction>
            <ode>
              <mu>0.01</mu>
              <mu2>0.01</mu2>
            </ode>
          </friction>
        </surface>
      </collision>
      <visual name="visual">
        <geometry>
          <sphere>
            <radius>0.05</radius>
          </sphere>
        </geometry>
        <material>
          <ambient>0.3 0.3 0.3 1</ambient>
          <diffuse>0.4 0.4 0.4 1</diffuse>
        </material>
      </visual>
    </link>
    
    <!-- Left Wheel Joint -->
    <joint name="left_wheel_joint" type="revolute">
      <parent>base_link</parent>
      <child>left_wheel</child>
      <axis>
        <xyz>0 0 1</xyz>
        <limit>
          <lower>-1e16</lower>
          <upper>1e16</upper>
        </limit>
      </axis>
    </joint>
    
    <!-- Right Wheel Joint -->
    <joint name="right_wheel_joint" type="revolute">
      <parent>base_link</parent>
      <child>right_wheel</child>
      <axis>
        <xyz>0 0 1</xyz>
        <limit>
          <lower>-1e16</lower>
          <upper>1e16</upper>
        </limit>
      </axis>
    </joint>
    
    <!-- Caster Wheel Joint -->
    <joint name="caster_wheel_joint" type="ball">
      <parent>base_link</parent>
      <child>caster_wheel</child>
    </joint>
    
    <!-- Differential Drive Plugin -->
    <plugin filename="gz-sim-diff-drive-system" name="gz::sim::systems::DiffDrive">
      <left_joint>left_wheel_joint</left_joint>
      <right_joint>right_wheel_joint</right_joint>
      <wheel_separation>0.5</wheel_separation>
      <wheel_radius>0.15</wheel_radius>
      <odom_publish_frequency>50</odom_publish_frequency>
      <topic>cmd_vel</topic>
      <odom_topic>odom</odom_topic>
      <tf_topic>tf</tf_topic>
      <frame_id>odom</frame_id>
      <child_frame_id>base_link</child_frame_id>
    </plugin>
    
    <!-- Pose Publisher -->
    <plugin filename="gz-sim-pose-publisher-system" name="gz::sim::systems::PosePublisher">
      <publish_link_pose>true</publish_link_pose>
      <publish_sensor_pose>false</publish_sensor_pose>
      <publish_collision_pose>false</publish_collision_pose>
      <publish_visual_pose>false</publish_visual_pose>
      <publish_nested_model_pose>false</publish_nested_model_pose>
      <update_frequency>50</update_frequency>
    </plugin>
    
  </model>
</sdf>